terminate called after throwing an instance of 'std::_Nested_exception<std::runtime_error>'
  what():  Cannot open: nonexistent file
