terminate called after throwing an instance of 'std::out_of_range'
  what():  vector::_M_range_check: __n (which is 5) >= this->size() (which is 2)
