42
42
terminate called after throwing an instance of 'std::runtime_error'
  what():  42.0
